[2023-11-26T19:07:54.003+0000] {taskinstance.py:1157} INFO - Dependencies all met for dep_context=non-requeueable deps ti=<TaskInstance: your_etl_dag.download_transaction_logs manual__2023-11-26T15:14:20.659946+00:00 [queued]>
[2023-11-26T19:07:54.029+0000] {taskinstance.py:1157} INFO - Dependencies all met for dep_context=requeueable deps ti=<TaskInstance: your_etl_dag.download_transaction_logs manual__2023-11-26T15:14:20.659946+00:00 [queued]>
[2023-11-26T19:07:54.030+0000] {taskinstance.py:1359} INFO - Starting attempt 4 of 4
[2023-11-26T19:07:54.075+0000] {taskinstance.py:1380} INFO - Executing <Task(DownloadTransactionLogsOperator): download_transaction_logs> on 2023-11-26 15:14:20.659946+00:00
[2023-11-26T19:07:54.111+0000] {standard_task_runner.py:57} INFO - Started process 184 to run task
[2023-11-26T19:07:54.187+0000] {standard_task_runner.py:84} INFO - Running: ['***', 'tasks', 'run', 'your_etl_dag', 'download_transaction_logs', 'manual__2023-11-26T15:14:20.659946+00:00', '--job-id', '39', '--raw', '--subdir', 'DAGS_FOLDER/dag.py', '--cfg-path', '/tmp/tmp3iq_xa5p']
[2023-11-26T19:07:54.236+0000] {standard_task_runner.py:85} INFO - Job 39: Subtask download_transaction_logs
[2023-11-26T19:07:54.597+0000] {task_command.py:415} INFO - Running <TaskInstance: your_etl_dag.download_transaction_logs manual__2023-11-26T15:14:20.659946+00:00 [running]> on host e90f0e94c48e
[2023-11-26T19:07:55.089+0000] {taskinstance.py:1660} INFO - Exporting env vars: AIRFLOW_CTX_DAG_OWNER='you' AIRFLOW_CTX_DAG_ID='your_etl_dag' AIRFLOW_CTX_TASK_ID='download_transaction_logs' AIRFLOW_CTX_EXECUTION_DATE='2023-11-26T15:14:20.659946+00:00' AIRFLOW_CTX_TRY_NUMBER='4' AIRFLOW_CTX_DAG_RUN_ID='manual__2023-11-26T15:14:20.659946+00:00'
[2023-11-26T19:07:55.362+0000] {taskinstance.py:1935} ERROR - Task failed with exception
Traceback (most recent call last):
  File "/opt/airflow/dags/custom_operators.py", line 88, in execute
    download_transaction_logs_to_csv()
  File "/opt/airflow/dags/custom_operators.py", line 24, in download_transaction_logs_to_csv
    transaction_logs_data.to_csv(
  File "/home/airflow/.local/lib/python3.8/site-packages/pandas/core/generic.py", line 3772, in to_csv
    return DataFrameRenderer(formatter).to_csv(
  File "/home/airflow/.local/lib/python3.8/site-packages/pandas/io/formats/format.py", line 1186, in to_csv
    csv_formatter.save()
  File "/home/airflow/.local/lib/python3.8/site-packages/pandas/io/formats/csvs.py", line 240, in save
    with get_handle(
  File "/home/airflow/.local/lib/python3.8/site-packages/pandas/io/common.py", line 737, in get_handle
    check_parent_directory(str(handle))
  File "/home/airflow/.local/lib/python3.8/site-packages/pandas/io/common.py", line 600, in check_parent_directory
    raise OSError(rf"Cannot save file into a non-existent directory: '{parent}'")
OSError: Cannot save file into a non-existent directory: '/data'
[2023-11-26T19:07:55.397+0000] {taskinstance.py:1398} INFO - Marking task as FAILED. dag_id=your_etl_dag, task_id=download_transaction_logs, execution_date=20231126T151420, start_date=20231126T190754, end_date=20231126T190755
[2023-11-26T19:07:55.444+0000] {standard_task_runner.py:104} ERROR - Failed to execute job 39 for task download_transaction_logs (Cannot save file into a non-existent directory: '/data'; 184)
[2023-11-26T19:07:55.520+0000] {local_task_job_runner.py:228} INFO - Task exited with return code 1
[2023-11-26T19:07:55.606+0000] {taskinstance.py:2776} INFO - 0 downstream tasks scheduled from follow-on schedule check
