[2023-11-26T19:07:55.250+0000] {taskinstance.py:1157} INFO - Dependencies all met for dep_context=non-requeueable deps ti=<TaskInstance: your_etl_dag.download_transaction_logs manual__2023-11-26T18:58:32.893551+00:00 [queued]>
[2023-11-26T19:07:55.313+0000] {taskinstance.py:1157} INFO - Dependencies all met for dep_context=requeueable deps ti=<TaskInstance: your_etl_dag.download_transaction_logs manual__2023-11-26T18:58:32.893551+00:00 [queued]>
[2023-11-26T19:07:55.313+0000] {taskinstance.py:1359} INFO - Starting attempt 2 of 2
[2023-11-26T19:07:55.374+0000] {taskinstance.py:1380} INFO - Executing <Task(DownloadTransactionLogsOperator): download_transaction_logs> on 2023-11-26 18:58:32.893551+00:00
[2023-11-26T19:07:55.408+0000] {standard_task_runner.py:57} INFO - Started process 191 to run task
[2023-11-26T19:07:55.443+0000] {standard_task_runner.py:84} INFO - Running: ['***', 'tasks', 'run', 'your_etl_dag', 'download_transaction_logs', 'manual__2023-11-26T18:58:32.893551+00:00', '--job-id', '46', '--raw', '--subdir', 'DAGS_FOLDER/dag.py', '--cfg-path', '/tmp/tmpmn4ouxtt']
[2023-11-26T19:07:55.477+0000] {standard_task_runner.py:85} INFO - Job 46: Subtask download_transaction_logs
[2023-11-26T19:07:55.705+0000] {task_command.py:415} INFO - Running <TaskInstance: your_etl_dag.download_transaction_logs manual__2023-11-26T18:58:32.893551+00:00 [running]> on host e90f0e94c48e
[2023-11-26T19:07:56.005+0000] {taskinstance.py:1660} INFO - Exporting env vars: AIRFLOW_CTX_DAG_OWNER='you' AIRFLOW_CTX_DAG_ID='your_etl_dag' AIRFLOW_CTX_TASK_ID='download_transaction_logs' AIRFLOW_CTX_EXECUTION_DATE='2023-11-26T18:58:32.893551+00:00' AIRFLOW_CTX_TRY_NUMBER='2' AIRFLOW_CTX_DAG_RUN_ID='manual__2023-11-26T18:58:32.893551+00:00'
[2023-11-26T19:07:56.205+0000] {taskinstance.py:1935} ERROR - Task failed with exception
Traceback (most recent call last):
  File "/opt/airflow/dags/custom_operators.py", line 88, in execute
    download_transaction_logs_to_csv()
  File "/opt/airflow/dags/custom_operators.py", line 24, in download_transaction_logs_to_csv
    transaction_logs_data.to_csv(
  File "/home/airflow/.local/lib/python3.8/site-packages/pandas/core/generic.py", line 3772, in to_csv
    return DataFrameRenderer(formatter).to_csv(
  File "/home/airflow/.local/lib/python3.8/site-packages/pandas/io/formats/format.py", line 1186, in to_csv
    csv_formatter.save()
  File "/home/airflow/.local/lib/python3.8/site-packages/pandas/io/formats/csvs.py", line 240, in save
    with get_handle(
  File "/home/airflow/.local/lib/python3.8/site-packages/pandas/io/common.py", line 737, in get_handle
    check_parent_directory(str(handle))
  File "/home/airflow/.local/lib/python3.8/site-packages/pandas/io/common.py", line 600, in check_parent_directory
    raise OSError(rf"Cannot save file into a non-existent directory: '{parent}'")
OSError: Cannot save file into a non-existent directory: '/data'
[2023-11-26T19:07:56.224+0000] {taskinstance.py:1398} INFO - Marking task as FAILED. dag_id=your_etl_dag, task_id=download_transaction_logs, execution_date=20231126T185832, start_date=20231126T190755, end_date=20231126T190756
[2023-11-26T19:07:56.233+0000] {standard_task_runner.py:104} ERROR - Failed to execute job 46 for task download_transaction_logs (Cannot save file into a non-existent directory: '/data'; 191)
[2023-11-26T19:07:56.255+0000] {local_task_job_runner.py:228} INFO - Task exited with return code 1
[2023-11-26T19:07:56.271+0000] {taskinstance.py:2776} INFO - 0 downstream tasks scheduled from follow-on schedule check
