[2023-11-26T18:31:37.990+0000] {taskinstance.py:1157} INFO - Dependencies all met for dep_context=non-requeueable deps ti=<TaskInstance: your_etl_dag.download_currency manual__2023-11-26T18:31:35.285407+00:00 [queued]>
[2023-11-26T18:31:38.003+0000] {taskinstance.py:1157} INFO - Dependencies all met for dep_context=requeueable deps ti=<TaskInstance: your_etl_dag.download_currency manual__2023-11-26T18:31:35.285407+00:00 [queued]>
[2023-11-26T18:31:38.006+0000] {taskinstance.py:1359} INFO - Starting attempt 1 of 2
[2023-11-26T18:31:38.021+0000] {taskinstance.py:1380} INFO - Executing <Task(DownloadCurrencyOperator): download_currency> on 2023-11-26 18:31:35.285407+00:00
[2023-11-26T18:31:38.035+0000] {standard_task_runner.py:57} INFO - Started process 224 to run task
[2023-11-26T18:31:38.049+0000] {standard_task_runner.py:84} INFO - Running: ['***', 'tasks', 'run', 'your_etl_dag', 'download_currency', 'manual__2023-11-26T18:31:35.285407+00:00', '--job-id', '20', '--raw', '--subdir', 'DAGS_FOLDER/dag.py', '--cfg-path', '/tmp/tmpx566gt5h']
[2023-11-26T18:31:38.054+0000] {standard_task_runner.py:85} INFO - Job 20: Subtask download_currency
[2023-11-26T18:31:38.139+0000] {task_command.py:415} INFO - Running <TaskInstance: your_etl_dag.download_currency manual__2023-11-26T18:31:35.285407+00:00 [running]> on host 616efbdf83b0
[2023-11-26T18:31:38.207+0000] {taskinstance.py:1660} INFO - Exporting env vars: AIRFLOW_CTX_DAG_OWNER='you' AIRFLOW_CTX_DAG_ID='your_etl_dag' AIRFLOW_CTX_TASK_ID='download_currency' AIRFLOW_CTX_EXECUTION_DATE='2023-11-26T18:31:35.285407+00:00' AIRFLOW_CTX_TRY_NUMBER='1' AIRFLOW_CTX_DAG_RUN_ID='manual__2023-11-26T18:31:35.285407+00:00'
[2023-11-26T18:31:38.487+0000] {taskinstance.py:1935} ERROR - Task failed with exception
Traceback (most recent call last):
  File "/opt/airflow/dags/custom_operators.py", line 78, in execute
    download_currency_to_csv()
  File "/opt/airflow/dags/custom_operators.py", line 14, in download_currency_to_csv
    os.makedirs("/data", exist_ok=True)
  File "/usr/local/lib/python3.8/os.py", line 223, in makedirs
    mkdir(name, mode)
PermissionError: [Errno 13] Permission denied: '/data'
[2023-11-26T18:31:38.496+0000] {taskinstance.py:1398} INFO - Marking task as UP_FOR_RETRY. dag_id=your_etl_dag, task_id=download_currency, execution_date=20231126T183135, start_date=20231126T183137, end_date=20231126T183138
[2023-11-26T18:31:38.508+0000] {standard_task_runner.py:104} ERROR - Failed to execute job 20 for task download_currency ([Errno 13] Permission denied: '/data'; 224)
[2023-11-26T18:31:38.544+0000] {local_task_job_runner.py:228} INFO - Task exited with return code 1
[2023-11-26T18:31:38.571+0000] {taskinstance.py:2776} INFO - 0 downstream tasks scheduled from follow-on schedule check
