[2023-11-26T19:29:36.139+0000] {taskinstance.py:1157} INFO - Dependencies all met for dep_context=non-requeueable deps ti=<TaskInstance: etl_dag.merge_data manual__2023-11-26T19:23:38.629095+00:00 [queued]>
[2023-11-26T19:29:36.147+0000] {taskinstance.py:1157} INFO - Dependencies all met for dep_context=requeueable deps ti=<TaskInstance: etl_dag.merge_data manual__2023-11-26T19:23:38.629095+00:00 [queued]>
[2023-11-26T19:29:36.147+0000] {taskinstance.py:1359} INFO - Starting attempt 1 of 2
[2023-11-26T19:29:36.305+0000] {taskinstance.py:1380} INFO - Executing <Task(MergeDataOperator): merge_data> on 2023-11-26 19:23:38.629095+00:00
[2023-11-26T19:29:36.313+0000] {standard_task_runner.py:57} INFO - Started process 185 to run task
[2023-11-26T19:29:36.319+0000] {standard_task_runner.py:84} INFO - Running: ['***', 'tasks', 'run', 'etl_dag', 'merge_data', 'manual__2023-11-26T19:23:38.629095+00:00', '--job-id', '69', '--raw', '--subdir', 'DAGS_FOLDER/dag.py', '--cfg-path', '/tmp/tmp70k7ztvo']
[2023-11-26T19:29:36.327+0000] {standard_task_runner.py:85} INFO - Job 69: Subtask merge_data
[2023-11-26T19:29:36.379+0000] {task_command.py:415} INFO - Running <TaskInstance: etl_dag.merge_data manual__2023-11-26T19:23:38.629095+00:00 [running]> on host d3fc1b5682ee
[2023-11-26T19:29:36.428+0000] {taskinstance.py:1660} INFO - Exporting env vars: AIRFLOW_CTX_DAG_OWNER='you' AIRFLOW_CTX_DAG_ID='etl_dag' AIRFLOW_CTX_TASK_ID='merge_data' AIRFLOW_CTX_EXECUTION_DATE='2023-11-26T19:23:38.629095+00:00' AIRFLOW_CTX_TRY_NUMBER='1' AIRFLOW_CTX_DAG_RUN_ID='manual__2023-11-26T19:23:38.629095+00:00'
[2023-11-26T19:29:36.430+0000] {taskinstance.py:1935} ERROR - Task failed with exception
Traceback (most recent call last):
  File "/opt/airflow/dags/custom_operators.py", line 101, in execute
    merge_data()
  File "/opt/airflow/dags/custom_operators.py", line 36, in merge_data
    currency_data = pd.read_csv(f"/data/currency_{date}.csv")
  File "/home/airflow/.local/lib/python3.8/site-packages/pandas/io/parsers/readers.py", line 912, in read_csv
    return _read(filepath_or_buffer, kwds)
  File "/home/airflow/.local/lib/python3.8/site-packages/pandas/io/parsers/readers.py", line 577, in _read
    parser = TextFileReader(filepath_or_buffer, **kwds)
  File "/home/airflow/.local/lib/python3.8/site-packages/pandas/io/parsers/readers.py", line 1407, in __init__
    self._engine = self._make_engine(f, self.engine)
  File "/home/airflow/.local/lib/python3.8/site-packages/pandas/io/parsers/readers.py", line 1661, in _make_engine
    self.handles = get_handle(
  File "/home/airflow/.local/lib/python3.8/site-packages/pandas/io/common.py", line 859, in get_handle
    handle = open(
FileNotFoundError: [Errno 2] No such file or directory: '/data/currency_2021-01-01.csv'
[2023-11-26T19:29:36.436+0000] {taskinstance.py:1398} INFO - Marking task as UP_FOR_RETRY. dag_id=etl_dag, task_id=merge_data, execution_date=20231126T192338, start_date=20231126T192936, end_date=20231126T192936
[2023-11-26T19:29:36.443+0000] {standard_task_runner.py:104} ERROR - Failed to execute job 69 for task merge_data ([Errno 2] No such file or directory: '/data/currency_2021-01-01.csv'; 185)
[2023-11-26T19:29:36.455+0000] {local_task_job_runner.py:228} INFO - Task exited with return code 1
[2023-11-26T19:29:36.471+0000] {taskinstance.py:2776} INFO - 0 downstream tasks scheduled from follow-on schedule check
