[2023-11-26T19:07:54.584+0000] {taskinstance.py:1157} INFO - Dependencies all met for dep_context=non-requeueable deps ti=<TaskInstance: your_etl_dag.download_currency manual__2023-11-26T18:58:32.893551+00:00 [queued]>
[2023-11-26T19:07:54.616+0000] {taskinstance.py:1157} INFO - Dependencies all met for dep_context=requeueable deps ti=<TaskInstance: your_etl_dag.download_currency manual__2023-11-26T18:58:32.893551+00:00 [queued]>
[2023-11-26T19:07:54.619+0000] {taskinstance.py:1359} INFO - Starting attempt 2 of 2
[2023-11-26T19:07:54.677+0000] {taskinstance.py:1380} INFO - Executing <Task(DownloadCurrencyOperator): download_currency> on 2023-11-26 18:58:32.893551+00:00
[2023-11-26T19:07:54.697+0000] {standard_task_runner.py:57} INFO - Started process 187 to run task
[2023-11-26T19:07:54.755+0000] {standard_task_runner.py:84} INFO - Running: ['***', 'tasks', 'run', 'your_etl_dag', 'download_currency', 'manual__2023-11-26T18:58:32.893551+00:00', '--job-id', '44', '--raw', '--subdir', 'DAGS_FOLDER/dag.py', '--cfg-path', '/tmp/tmpbvskcfhx']
[2023-11-26T19:07:54.782+0000] {standard_task_runner.py:85} INFO - Job 44: Subtask download_currency
[2023-11-26T19:07:55.180+0000] {task_command.py:415} INFO - Running <TaskInstance: your_etl_dag.download_currency manual__2023-11-26T18:58:32.893551+00:00 [running]> on host e90f0e94c48e
[2023-11-26T19:07:55.591+0000] {taskinstance.py:1660} INFO - Exporting env vars: AIRFLOW_CTX_DAG_OWNER='you' AIRFLOW_CTX_DAG_ID='your_etl_dag' AIRFLOW_CTX_TASK_ID='download_currency' AIRFLOW_CTX_EXECUTION_DATE='2023-11-26T18:58:32.893551+00:00' AIRFLOW_CTX_TRY_NUMBER='2' AIRFLOW_CTX_DAG_RUN_ID='manual__2023-11-26T18:58:32.893551+00:00'
[2023-11-26T19:07:55.741+0000] {taskinstance.py:1935} ERROR - Task failed with exception
Traceback (most recent call last):
  File "/opt/airflow/dags/custom_operators.py", line 77, in execute
    download_currency_to_csv()
  File "/opt/airflow/dags/custom_operators.py", line 14, in download_currency_to_csv
    currency_data.to_csv(
  File "/home/airflow/.local/lib/python3.8/site-packages/pandas/core/generic.py", line 3772, in to_csv
    return DataFrameRenderer(formatter).to_csv(
  File "/home/airflow/.local/lib/python3.8/site-packages/pandas/io/formats/format.py", line 1186, in to_csv
    csv_formatter.save()
  File "/home/airflow/.local/lib/python3.8/site-packages/pandas/io/formats/csvs.py", line 240, in save
    with get_handle(
  File "/home/airflow/.local/lib/python3.8/site-packages/pandas/io/common.py", line 737, in get_handle
    check_parent_directory(str(handle))
  File "/home/airflow/.local/lib/python3.8/site-packages/pandas/io/common.py", line 600, in check_parent_directory
    raise OSError(rf"Cannot save file into a non-existent directory: '{parent}'")
OSError: Cannot save file into a non-existent directory: '/data'
[2023-11-26T19:07:55.800+0000] {taskinstance.py:1398} INFO - Marking task as FAILED. dag_id=your_etl_dag, task_id=download_currency, execution_date=20231126T185832, start_date=20231126T190754, end_date=20231126T190755
[2023-11-26T19:07:55.828+0000] {standard_task_runner.py:104} ERROR - Failed to execute job 44 for task download_currency (Cannot save file into a non-existent directory: '/data'; 187)
[2023-11-26T19:07:55.893+0000] {local_task_job_runner.py:228} INFO - Task exited with return code 1
[2023-11-26T19:07:56.020+0000] {taskinstance.py:2776} INFO - 0 downstream tasks scheduled from follow-on schedule check
