[2023-11-26T19:30:03.721+0000] {taskinstance.py:1157} INFO - Dependencies all met for dep_context=non-requeueable deps ti=<TaskInstance: etl_dag.merge_data manual__2023-11-26T19:30:00.936846+00:00 [queued]>
[2023-11-26T19:30:03.730+0000] {taskinstance.py:1157} INFO - Dependencies all met for dep_context=requeueable deps ti=<TaskInstance: etl_dag.merge_data manual__2023-11-26T19:30:00.936846+00:00 [queued]>
[2023-11-26T19:30:03.731+0000] {taskinstance.py:1359} INFO - Starting attempt 1 of 2
[2023-11-26T19:30:03.821+0000] {taskinstance.py:1380} INFO - Executing <Task(MergeDataOperator): merge_data> on 2023-11-26 19:30:00.936846+00:00
[2023-11-26T19:30:03.825+0000] {standard_task_runner.py:57} INFO - Started process 207 to run task
[2023-11-26T19:30:03.828+0000] {standard_task_runner.py:84} INFO - Running: ['***', 'tasks', 'run', 'etl_dag', 'merge_data', 'manual__2023-11-26T19:30:00.936846+00:00', '--job-id', '72', '--raw', '--subdir', 'DAGS_FOLDER/dag.py', '--cfg-path', '/tmp/tmpe7qibp_8']
[2023-11-26T19:30:03.831+0000] {standard_task_runner.py:85} INFO - Job 72: Subtask merge_data
[2023-11-26T19:30:03.866+0000] {task_command.py:415} INFO - Running <TaskInstance: etl_dag.merge_data manual__2023-11-26T19:30:00.936846+00:00 [running]> on host d3fc1b5682ee
[2023-11-26T19:30:03.916+0000] {taskinstance.py:1660} INFO - Exporting env vars: AIRFLOW_CTX_DAG_OWNER='you' AIRFLOW_CTX_DAG_ID='etl_dag' AIRFLOW_CTX_TASK_ID='merge_data' AIRFLOW_CTX_EXECUTION_DATE='2023-11-26T19:30:00.936846+00:00' AIRFLOW_CTX_TRY_NUMBER='1' AIRFLOW_CTX_DAG_RUN_ID='manual__2023-11-26T19:30:00.936846+00:00'
[2023-11-26T19:30:03.918+0000] {taskinstance.py:1935} ERROR - Task failed with exception
Traceback (most recent call last):
  File "/opt/airflow/dags/custom_operators.py", line 101, in execute
    merge_data()
  File "/opt/airflow/dags/custom_operators.py", line 36, in merge_data
    currency_data = pd.read_csv(f"/data/currency_{date}.csv")
  File "/home/airflow/.local/lib/python3.8/site-packages/pandas/io/parsers/readers.py", line 912, in read_csv
    return _read(filepath_or_buffer, kwds)
  File "/home/airflow/.local/lib/python3.8/site-packages/pandas/io/parsers/readers.py", line 577, in _read
    parser = TextFileReader(filepath_or_buffer, **kwds)
  File "/home/airflow/.local/lib/python3.8/site-packages/pandas/io/parsers/readers.py", line 1407, in __init__
    self._engine = self._make_engine(f, self.engine)
  File "/home/airflow/.local/lib/python3.8/site-packages/pandas/io/parsers/readers.py", line 1661, in _make_engine
    self.handles = get_handle(
  File "/home/airflow/.local/lib/python3.8/site-packages/pandas/io/common.py", line 859, in get_handle
    handle = open(
FileNotFoundError: [Errno 2] No such file or directory: '/data/currency_2021-01-01.csv'
[2023-11-26T19:30:03.924+0000] {taskinstance.py:1398} INFO - Marking task as UP_FOR_RETRY. dag_id=etl_dag, task_id=merge_data, execution_date=20231126T193000, start_date=20231126T193003, end_date=20231126T193003
[2023-11-26T19:30:03.931+0000] {standard_task_runner.py:104} ERROR - Failed to execute job 72 for task merge_data ([Errno 2] No such file or directory: '/data/currency_2021-01-01.csv'; 207)
[2023-11-26T19:30:03.962+0000] {local_task_job_runner.py:228} INFO - Task exited with return code 1
[2023-11-26T19:30:03.980+0000] {taskinstance.py:2776} INFO - 0 downstream tasks scheduled from follow-on schedule check
